Workbook
Name BIMABD: 'Monitoring BIM April 2026'!$R$8:$R$116
Name BIMBAFlushing: 'Monitoring BIM April 2026'!$AP$8:$AP$116
Name BIMBAHydro: 'Monitoring BIM April 2026'!$AN$8:$AN$116
Name BIMBAPL: 'Monitoring BIM April 2026'!$AJ$8:$AJ$116
Name BIMBASinggem: 'Monitoring BIM April 2026'!$AR$8:$AR$116
Name BIMBATC: 'Monitoring BIM April 2026'!$AD$8:$AD$116
Name BIMBATestPit: 'Monitoring BIM April 2026'!$AX$8:$AX$116
Name BIMBATF: 'Monitoring BIM April 2026'!$AL$8:$AL$116
Name BIMDPPK: 'Monitoring BIM April 2026'!$N$8:$N$116
Name BIMDPPP: 'Monitoring BIM April 2026'!$BM$8:$BM$116
Name BIMJustek: 'Monitoring BIM April 2026'!$AT$8:$AT$116
Name BIMJustfin: 'Monitoring BIM April 2026'!$AV$8:$AV$116
Name BIMLHLMLB: 'Monitoring BIM April 2026'!$BF$8:$BF$116
Name BIMMC0: 'Monitoring BIM April 2026'!$AF$8:$AF$116
Name BIMMC100: 'Monitoring BIM April 2026'!$AH$8:$AH$116
Name BIMPelatihan: 'Monitoring BIM April 2026'!$T$8:$T$116
Name BIMPerizinan: 'Monitoring BIM April 2026'!$V$8:$V$116
Name BIMPKPI: 'Monitoring BIM April 2026'!$P$8:$P$116
Name BIMPropMod: 'Monitoring BIM April 2026'!$BH$8:$BH$116
Name BIMRAB: 'Monitoring BIM April 2026'!$Z$8:$Z$116
Name BIMRDA: 'Monitoring BIM April 2026'!$X$8:$X$116
Name BIMRNA: 'Monitoring BIM April 2026'!$AB$8:$AB$116
Name BIMStatusProyek: 'Monitoring BIM April 2026'!$I$8:$I$116
Name BIMUjiLab: 'Monitoring BIM April 2026'!$AZ$8:$AZ$116
Name BIMUjiLogger: 'Monitoring BIM April 2026'!$BB$8:$BB$116
Name BIMUmum: 'Monitoring BIM April 2026'!$BD$8:$BD$116
Name Kategori: #REF!
Name KomitmenABD: #REF!
Name KomitmenBAFlush: #REF!
Name KomitmenBAHydro: #REF!
Name KomitmenBAMC0: #REF!
Name KomitmenBAMC100: #REF!
Name KomitmenBAPL: #REF!
Name KomitmenBASinggem: #REF!
Name KomitmenBATC: #REF!
Name KomitmenBATestpit: #REF!
Name KomitmenBATF: #REF!
Name KomitmenDataLogger: #REF!
Name KomitmenDPPK: #REF!
Name KomitmenJusfin: #REF!
Name KomitmenJustek: #REF!
Name KomitmenLHLMLB: #REF!
Name KomitmenPelatihan: #REF!
Name KomitmenPerizinan: #REF!
Name KomitmenPKPI: #REF!
Name KomitmenPropmod: #REF!
Name KomitmenRAB: #REF!
Name KomitmenRDA: #REF!
Name KomitmenRNA: #REF!
Name KomitmenSubmitDP3: #REF!
Name KomitmenUjiLab: #REF!
Name KomitmenUmumK3: #REF!
Name PICABD: #REF!
Name PICBAFlush: #REF!
Name PICBAHydro: #REF!
Name PICBAMC0: #REF!
Name PICBAMC100: #REF!
Name PICBAPL: #REF!
Name PICBASinggem: #REF!
Name PICBATC: #REF!

Sheet Database MK
Y1: PC 070 KELURAHAN CAKUNG TIMUR, ROROTAN, UJUNG MENTENG KECAMATAN CAKUNG, CILINCING | AA1: =17+64 -> 81 | AC1: a | AN1: "Volume BA MC-0" | AO1: Volume BA MC-0 SUM -> | BH1: S.14 Progres : 20.762 m S.17 Progres : 4.857 m | BJ1: Total Panjang Pipa Aktual (Sum->)3 | BM1: =678-218 -> 460 | BS1: =18591-17446 -> 1145 | DO1: A
D2: DATABASE PROJECT GREENFIELD | W2: =W3/N3 -> 0.44879171 | BJ2: 60.5 | CP2: Cut Off | CU2: UPDATE 21/06/26 | CX2: UPDATE 21/06/26
D3: =SUBTOTAL(3,D5:D468) -> 464 | N3: =SUBTOTAL(9,N5:N468) -> 1785705 | R3: =SUBTOTAL(101,R5:R509) -> #N/A | S3: =SUBTOTAL(101,S5:S509) -> 0.94650021 | T3: =SUBTOTAL(101,T5:T509) -> 0.61404132 | U3: =SUBTOTAL(101,U5:U509) -> -0.3026509 | V3: =SUBTOTAL(9,V5:V509) -> 1247361.2 | W3: =SUBTOTAL(9,W5:W509) -> 801409.6 | X3: =SUBTOTAL(9,W5:W468) -> 801409.6 | Z3: =SUBTOTAL(9,Z5:Z440) -> 6.2117545e+12 | AA3: =SUBTOTAL(9,AA5:AA440) -> 5130059273839 | AB3: =SUBTOTAL(9,AB5:AB440) -> 2.1482914e+12 | AC3: =SUBTOTAL(9,AC5:AC440) -> 1.1114721e+11 | AD3: =SUBTOTAL(9,AD5:AD440) -> 1.383127e+12 | AE3: =SUBTOTAL(9,AE5:AE440) -> 6.4335666e+11 | AF3: =SUBTOTAL(9,AF5:AF440) -> 1.066056e+10 | AN3: =SUBTOTAL(9,AN5:AN468) -> 1050956.2 | AO3: =SUBTOTAL(9,AO5:AO468) -> 891629.36 | BJ3: =SUBTOTAL(9,BJ5:BJ468) -> 801409.6 | BK3: =SUBTOTAL(9,BK5:BK468) -> 354606.06 | BL3: =SUBTOTAL(9,BL5:BL344) -> 204036.1 | BM3: =SUBTOTAL(9,BM5:BM344) -> 87278 | BN3: =SUBTOTAL(9,BN5:BN344) -> 48867 | BO3: =SUBTOTAL(9,BO5:BO344) -> 18487.6 | BP3: =SUBTOTAL(9,BP5:BP344) -> 7344.4 | BQ3: =SUBTOTAL(9,BQ5:BQ344) -> 13998.3 | BR3: =SUBTOTAL(9,BR5:BR344) -> 52 | BS3: =SUBTOTAL(9,BS5:BS344) -> 8097.83 | ... CI3: =SUBTOTAL(9,CI5:CI344) -> 110201.8 | CJ3: =SUBTOTAL(9,CJ5:CJ468) -> 168796.08 | CP3: 46033 | CU3: =SUBTOTAL(9,CU5:CU468) -> 3.8924885e+12 | CV3: =SUBTOTAL(9,CV5:CV468) -> 3.8924885e+12 | CW3: =SUBTOTAL(9,CW5:CW468) -> 2.7595152e+12 | CX3: =SUBTOTAL(9,CX5:CX468) -> 2.7595152e+12 | DC3: =SUBTOTAL(3,DC5:DC468) -> 319 | DD3: =SUBTOTAL(9,DD5:DD468) -> 5.9708523e+12 | DG3: =SUBTOTAL(3,DG5:DG468) -> 316 | DH3: =SUBTOTAL(9,DH5:DH468) -> 5.9373923e+12 | DM3: =SUBTOTAL(3,DM345:DM439) -> 92 | DN3: =SUBTOTAL(3,DN345:DN439) -> 95 | DO3: =SUBTOTAL(3,DO345:DO439) -> 92 | DP3: =SUBTOTAL(3,DP345:DP439) -> 38 | DR3: =SUBTOTAL(3,DR345:DR439) -> 95 | DX3: =SUBTOTAL(3,DX5:DX468) -> 309 | DY3: =SUBTOTAL(9,DY5:DY468) -> 11162 | DZ3: =SUBTOTAL(9,DZ5:DZ468) -> 11145 | EA3: =SUBTOTAL(3,EA345:EA439) -> 95 | EC3: =SUBTOTAL(9,EC5:EC468) -> 10437 | ED3: =SUBTOTAL(9,ED5:ED468) -> 10437 | EF3: =SUBTOTAL(101,EF5:EF468) -> 0.97352646 | EG3: =SUBTOTAL(101,EG5:EG468) -> 0.97352646 | EO3: =SUBTOTAL(9,EO5:EO468) -> 7318 | EP3: =SUBTOTAL(9,EP5:EP468) -> 7318 | EQ3: =SUBTOTAL(101,EQ5:EQ468) -> 0.8462814 | ER3: =SUBTOTAL(101,ER5:ER468) -> 0.8462814 | FP3: =SUBTOTAL(3,FP5:FP468) -> 33 | FQ3: =SUBTOTAL(3,FQ5:FQ468) -> 3 | FR3: =SUBTOTAL(3,FR5:FR468) -> 13 | FZ3: =SUBTOTAL(3,FZ5:FZ468) -> 158 | GC3: =SUBTOTAL(3,GC5:GC468) -> 421 | GF3: =SUBTOTAL(3,GF5:GF468) -> 423 | GJ3: =SUBTOTAL(3,GJ5:GJ468) -> 424 | GP3: *Pemasangan Pipa | GT3: =SUBTOTAL(3,GT5:GT468) -> 271 | GX3: =SUBTOTAL(3,GX5:GX468) -> 206 | HB3: =SUBTOTAL(3,HB5:HB468) -> 241 | HG3: =SUBTOTAL(3,HG5:HG468) -> 248 | HK3: =SUBTOTAL(3,HK5:HK468) -> 0 | HP3: =SUBTOTAL(3,HP5:HP468) -> 11 | HQ3: =SUBTOTAL(3,HQ5:HQ468) -> 233 | HW3: =SUBTOTAL(3,HW5:HW468) -> 233
B4: No | C4: No urut | D4: Proyek | E4: Kode Program | F4: Nama Program | G4: Jadwal TOK | H4: Schedule | I4: Sub-Proyek | J4: Status TOK | K4: Nama PM | L4: Kategori Pekerjaan | M4: Directorat | N4: Volume (m) | O4: Satuan | P4: Status Target | Q4: Status Aktual | R4: Column5 | S4: Target Progres (%) | T4: Progres Aktual (%) | U4: Deviasi (%) | V4: Volume BA MC-0 | W4: Total Panjang Pipa Aktual | X4: Lokasi, RAB dan Bobot | Y4: Lokasi | Z4: Nilai RAB Jaringan (file pa aji) | AA4: Kontrol Nilai RAB Jaringan (Include Ppn) | AB4: Nilai RAB Jaringan (Exclude Ppn) | AC4: RAB Kegiatan Umum | AD4: RAB Pemasangan | AE4: RAB Pengadaan | AF4: RAB Perizinan | AG4: Nilai RAB IOT | AH4: Total Bobot | AI4: Bobot Keg Umum | AJ4: Bobot Pemasangan | AK4: Bobot Pengadaan | AL4: Bobot Perizinan | AM4: Aktual Pipa Terpasang | AN4: "Volume BA MC-0" | AO4: Volume BA MC-0 SUM -> | AP4: Pipa 63 mm | AQ4: Pipa 90 mm | AR4: Pipa 110 mm | AS4: Pipa 160 mm | AT4: Pipa 200 mm | AU4: Pipa 250 mm | AV4: Pipa 315 mm | AW4: Pipa 350 mm | AX4: Pipa 400 mm | AY4: Pipa 500 mm | AZ4: Pipa 630 mm | BA4: Pipa 700 mm | BB4: Pipa 800 mm | BC4: Pipa 900 mm | BD4: Pipa 1,000 mm | BE4: Pipa 1,200 mm | BF4: Pipa 1,400 mm | BG4: Pipa 1,500 mm | BH4: Pipa 1,600 mm | BI4: Pipa 1,800 mm | BJ4: Total Panjang Pipa Aktual (Sum->)3 | BK4: Pipa 63 mm2 | BL4: Pipa 90 mm3 | BM4: Pipa 110 mm4 | BN4: Pipa 160 mm5 | BO4: Pipa 200 mm6 | BP4: Pipa 250 mm7 | BQ4: Pipa 315 mm8 | BR4: Pipa 350 mm9 | BS4: Pipa 400 mm10 | BT4: Pipa 500 mm11 | BU4: Pipa 630 mm12 | BV4: Pipa 700 mm13 | BW4: Pipa 800 mm14 | BX4: Pipa 900 mm15 | BY4: Pipa 1,000 mm16 | BZ4: Pipa 1,200 mm17 | CA4: Pipa 1,400 mm18 | CB4: Pipa 1,500 mm19 | CC4: Pipa 1,600 mm20 | CD4: Pipa 1,800 mm21 | CE4: Volume Penolakan Warga | CF4: Volume Private Area | CG4: Volume Sudah ada eksisting | CH4: Volume Tidak sesuai DED | CI4: Total Volume tidak dapat dipasang | CJ4: Volume Sisa Pekerjaan | CK4: Progres dan VOWD - RNA | CL4: Progres Keg. Umum (%) | CM4: Progres MOS (%) | CN4: Progres Pemasangan (%) | CO4: Progres Perizinan (%) | CP4: Progres Total Aktual (%) | CQ4: VOWD Keg. Umum (Rp) | CR4: VOWD Pengadaan (Rp) | CS4: VOWD Pemasangan (Rp) | CT4: VOWD Perizinan (Rp) | CU4: VOWD (kolom bantu) | CV4: VOWD Total (Rp) | CW4: Nilai RNA Update | CX4: Kolom Bantu RNA Update | CY4: PR-PO-MOS | CZ4: PLAN PR-PO ABJ start | DA4: PLAN PR-PO ABJ finish | DB4: PR Aktual (tanggal) | DC4: No PR | DD4: Nilai PR + Perizinan (Rp) | DE4: Review PR ABJ | DF4: PO Aktual (tanggal) | DG4: No PO | DH4: Nilai PO ABJ (Rp) | DI4: Review PO ABJ | DJ4: PLAN PR-PO BPM Jasa start | DK4: PLAN PR-PO BPM Jasa finish | DL4: PR Jasa Aktual (tanggal) | DM4: No PR Jasa | DN4: Review PR Jasa BPM | DO4: PO Jasa Aktual (tanggal) | DP4: No PO Jasa | DQ4: Nama Vendor | DR4: Review PO Jasa BPM | DS4: PLAN PR-PO BPM Material start | DT4: Forecast PO Start | DU4: PLAN PR-PO BPM Material finish | DV4: Forecast PO Finish | DW4: PR Material Aktual (tanggal) | DX4: No PR Material | DY4: Line PR | DZ4: Line PR (kolom bantu) | EA4: Review PR Material BPM | EB4: Tanggal Selesai PO Material | EC4: Line PO | ED4: Line PO (kolom bantu)2 | EE4: NO PO Material | EF4: PO Material Aktual (%) | EG4: UPDATE PO (kolom bantu) | EH4: Review PO Material BPM | EI4: Review PO Material | EJ4: PLAN MOS start | EK4: Forecast MOS Start | EL4: PLAN MOS finish | EM4: Forecast MOS Finish | EN4: Tanggal Selesai MOS | EO4: Line MOS | EP4: Line MOS (kolom bantu) | EQ4: Progres MOS | ER4: UPDATE MOS (kolom bantu) | ES4: Status MOS | ET4: Review MOS | EU4: PERMIT | EV4: PLAN PERMIT start | EW4: Forecast Perizinan Start | EX4: PLAN PERMIT finish | EY4: Forecast Perizinan Finish | EZ4: IPPJU | FA4: IPPJU2 | FB4: Persiapan Dokumen | FC4: Upload Jakevo | FD4: Gambar Rekomtek | FE4: Upload DBM | FF4: Survey IPPJU | FG4: Revisi Gambar Rekomtek | FH4: Proses Rekomtek | FI4: Rekomtek Terbit | FJ4: Proses Penerbitan Izin | FK4: Izin Terbit | FL4: Column2 | FM4: Tanggal Pengajuan Dokumen | FN4: Column4 | FO4: Tanggal Terbit/ Target Izin Terbit | FP4: Crossing Sungai | FQ4: Crossing Kereta | FR4: Crossing Toll | FS4: Status Perizinan | FT4: Status Izin | FU4: Remaining7 | FV4: Review14 | FW4: Remain7 | FX4: PLAN vs ACT | FY4: PLAN Penyerahan DPPK | FZ4: Aktual DPPK | GA4: Review | GB4: PLAN PCM | GC4: Tanggal Aktual PCM | GD4: Review PCM | GE4: PLAN Kick Off | GF4: Tanggal Aktual Kick Off | GG4: Review Kick Off | GH4: PLAN MC-0 start | GI4: PLAN MC-0 finish | GJ4: Tanggal Aktual MC-0 | GK4: Review MC-0 | GL4: PLAN KONSTRUKSI start | GM4: Forecast Konstruksi Start | GN4: PLAN KONSTRUKSI finish | GO4: Forecast Konstruksi Finish (s.d. Flushing) | GP4: Aktual Selesai Konstruksi* (tanggal) | GQ4: Review Konstruksi | GR4: PLAN Hydro Tes start | GS4: PLAN Hydro Tes finish | GT4: Hydro Tes Actual (tanggal) | GU4: Status Hydro | GV4: PLAN Interkoneksi start | GW4: PLAN Interkoneksi finish | GX4: Interkoneksi Actual (tanggal) | GY4: Status Interkoneksi | GZ4: PLAN Flushing start | HA4: PLAN Flushing finish | HB4: Flushing Actual (tanggal) | HC4: Status Flushing | HD4: PLAN TC start | HE4: Forecast TC dan MC-100 Start | HF4: PLAN TC finish | HG4: TC Aktual (tanggal) | HH4: Status TC | HI4: PLAN Reinstatement start | HJ4: PLAN Reinstatement finish | HK4: Reinstatement Aktual (tanggal) | HL4: Status Reinstatement | HM4: PLAN MC-100 start | HN4: PLAN MC-100 finish | HO4: Forecast MC-100 Finish | HP4: MC-100 (Pengukuran Lapangan) | HQ4: BA MC-100 Aktual (Verifikasi) | HR4: Review MC-100 | HS4: PLAN DPPP start | HT4: Forecast DPPP Start | HU4: PLAN DPPP finish | HV4: Forecast DPPP Finish | HW4: Aktual Submit DPPP (tanggal) | HX4: Review DPPP | HY4: Issue dan Forecast | HZ4: Isu | IA4: Isu2 | IC4: Durasi Kontrak (Month)
B5: =SUBTOTAL(3,$D$5:D5) -> 1 | C5: 1 | D5: SPAM Jatiluhur Hilir | E5: NPP23JTA A2.2.1a | F5: A2 - BKT DN1500 (Segmen 1.a BKT - Pondok Kopi) | G5: 45752 | H5: MS | I5: Trunk Main | K5: Muhrojin | L5: Pipa | M5: PMO 2 | N5: 877 | O5: m | P5: =IF(NOW()>Table1[[#This Row],[PLAN MC-100 start]],"Selesai Fisik dan Dokumen",IF(AND(Table1[[#This Row],[PLAN MC-100 start]]<=NOW(),NOW()<=Table1[[#This Row],[PLAN MC-100 finish]]),"MC-100",IF(AND(Table1[[#This Row],[PLAN TC start]]<=NOW(),NOW()<=Table1[[#This Row],[PLAN TC finish]]),"Tes Com",IF(AND(Table1[[#This Row],[PLAN KONSTRUKSI start]]<=NOW(),NOW()<=Table1[[#This Row],[PLAN KONSTRUKSI finish]]),"Proses Konstruksi",IF(AND(Table1[[#This Row],[PLAN MOS start]]<=NOW(),NOW()<=Table1[[#This Row],[PLAN MOS finish]]),"Proses MOS",IF(AND(Table1[[#This Row],[PLAN MC-0 start]]<=NOW(),NOW()<=Table1[[#This Row],[PLAN MC-0 finish]]),"MC-0",IF(AND(Table1[[#This Row],[PLAN PR-PO BPM Jasa start]]<=NOW(),NOW()<=Table1[[#This Row],[PLAN PR-PO BPM Material finish]]),"PR-PO BPM",IF(AND(Table1[[#This Row],[PLAN PR-PO ABJ start]]<=NOW(),NOW()<=Table1[[#This Row],[PLAN PR-PO ABJ finish]]),"PR-PO ABJ",IF(NOW()<Table1[[#This Row],[PLAN PR-PO ABJ finish]],"Persiapan",""))))))))) -> Selesai Fisik dan Dokumen | Q5: =IF(LEFT(Table1[[#This Row],[Review DPPP]],5)="Sudah","DPPP",IF(LEFT(Table1[[#This Row],[Review MC-100]],5)="Sudah","MC-100",IF(LEFT(Table1[[#This Row],[Status TC]],5)="Sudah","Tes Com",IF(Table1[[#This Row],[Status Flushing]]="Sudah","Flushing",IF(Table1[[#This Row],[Total Panjang Pipa Aktual (Sum->)3]]>0,"Proses Konstruksi",IF(LEFT(Table1[[#This Row],[Review MC-0]],5)="Sudah","MC-0",IF(LEFT(Table1[[#This Row],[Review Kick Off]],5)="Sudah","Kick Off Meeting",IF(LEFT(Table1[[#This Row],[Review PCM]],5)="Sudah","PCM",IF(LEFT(Table1[[#This Row],[Status MOS]],10)="Proses MOS","Proses MOS",IF(LEFT(Table1[[#This Row],[Review PO Jasa BPM]],5)="Sudah","PO Jasa BPM",IF(LEFT(Table1[[#This Row],[Review PR Jasa BPM]],5)="Sudah","PR Jasa BPM",IF(LEFT(Table1[[#This Row],[Review PO Material BPM]],5)="Sudah","PO Material BPM",IF(LEFT(Table1[[#This Row],[Review PR Material BPM]],5)="Sudah","PR Material BPM",IF(LEFT(Table1[[#This Row],[Review PO ABJ]],5)="Sudah","PO ABJ",IF(LEFT(Table1[[#This Row],[Review PR ABJ]],5)="Sudah","PR ABJ","Persiapan"))))))))))))))) -> DPPP | R5: #N/A | S5: 1 | T5: =Table1[[#This Row],[Progres Total Aktual (%)]] -> 1 | U5: =Table1[[#This Row],[Progres Aktual (%)]]-Table1[[#This Row],[Target Progres (%)]] -> 0 | V5: =Table1[[#This Row],["Volume BA MC-0"]] -> 0 | W5: =Table1[[#This Row],[Total Panjang Pipa Aktual (Sum->)3]] -> 852.5 | Y5: Jl. Basuki Rahmat, Bypass | Z5: 55647427855 | AA5: =ROUND((Table1[[#This Row],[Nilai RAB Jaringan (Exclude Ppn)]]-Table1[[#This Row],[RAB Perizinan]])*1.11+Table1[[#This Row],[RAB Perizinan]],0) -> 0 | AB5: =SUM(Table1[[#This Row],[RAB Kegiatan Umum]:[RAB Perizinan]]) -> 0 | AG5: 0 | AH5: =SUM(Table1[[#This Row],[Bobot Keg Umum]:[Bobot Perizinan]]) -> #DIV/0! | AI5: =Table1[[#This Row],[RAB Kegiatan Umum]]/Table1[[#This Row],[Nilai RAB Jaringan (Exclude Ppn)]] -> #DIV/0! | AJ5: =Table1[[#This Row],[RAB Pemasangan]]/Table1[[#This Row],[Nilai RAB Jaringan (Exclude Ppn)]] -> #DIV/0! | AK5: =Table1[[#This Row],[RAB Pengadaan]]/Table1[[#This Row],[Nilai RAB Jaringan (Exclude Ppn)]] -> #DIV/0! | AL5: =Table1[[#This Row],[RAB Perizinan]]/Table1[[#This Row],[Nilai RAB Jaringan (Exclude Ppn)]] -> #DIV/0! | AO5: =SUM(Table1[[#This Row],[Pipa 63 mm]:[Pipa 1,800 mm]]) -> 0 | BJ5: =SUM(Table1[[#This Row],[Pipa 63 mm2]:[Pipa 1,800 mm21]]) -> 852.5 | CB5: =522.5+267.6+62.4 -> 852.5 | CE5: 0 | CI5: =SUM(CE5:CH5) -> 0 | CJ5: =IF((Table1[[#This Row],["Volume BA MC-0"]]-Table1[[#This Row],[Total Panjang Pipa Aktual (Sum->)3]]-Table1[[#This Row],[Total Volume tidak dapat dipasang]])>=0,Table1[[#This Row],["Volume BA MC-0"]]-Table1[[#This Row],[Total Panjang Pipa Aktual (Sum->)3]]-Table1[[#This Row],[Total Volume tidak dapat dipasang]],0) -> 0 | CP5: =IFERROR(IF(Table1[[#This Row],[Nilai RNA Update]]>0,Table1[[#This Row],[Nilai RNA Update]]/Table1[[#This Row],[Nilai RNA Update]],IF(Table1[[#This Row],[VOWD Total (Rp)]]=0,IF(LEFT(Table1[[#This Row],[Review PO Material BPM]],5)="Sudah",Table1[[#This Row],[Progres MOS]]*80%*Table1[[#This Row],[Bobot Pengadaan]],Table1[[#This Row],[Progres MOS]]*60%*Table1[[#This Row],[Bobot Pengadaan]]),Table1[[#This Row],[VOWD Total (Rp)]]/Table1[[#This Row],[Kontrol Nilai RAB Jaringan (Include Ppn)]])),0) -> 1 | CQ5: =IFERROR(Table1[[#This Row],[Progres Keg. Umum (%)]]*Table1[[#This Row],[Nilai RAB Jaringan (file pa aji)]],0) -> 0 | CR5: =IFERROR(Table1[[#This Row],[Progres MOS (%)]]*Table1[[#This Row],[Nilai RAB Jaringan (file pa aji)]],0) -> 0 | CS5: =IFERROR(Table1[[#This Row],[Progres Pemasangan (%)]]*Table1[[#This Row],[Nilai RAB Jaringan (file pa aji)]],0) -> 0 | CT5: =IFERROR(Table1[[#This Row],[Progres Perizinan (%)]]*Table1[[#This Row],[Nilai RAB Jaringan (file pa aji)]],0) -> 0 | CU5: 49593687220 | CV5: 49593687220 | CW5: 49593687220 | CX5: =_xlfn.XLOOKUP(Table1[[#This Row],[Kode Program]],'[1]Breakdown VOWD Greenfield'!$E:$E,'[1]Breakdown VOWD Greenfield'!$AT:$AT) -> 49593687220 | CZ5: 45194 | DA5: 45228 | DB5: 45210 | DC5: AJC/2023/11/Q800/362 | DD5: 537590677279 | DE5: =IF(AND(Table1[[#This Row],[PR Aktual (tanggal)]]="",Table1[[#This Row],[PLAN PR-PO ABJ finish]]>=NOW()),"Belum, OnSchedule",IF(AND(Table1[[#This Row],[PR Aktual (tanggal)]]="",Table1[[#This Row],[PLAN PR-PO ABJ finish]]<NOW()),"Belum, Delay",IF(AND(Table1[[#This Row],[PR Aktual (tanggal)]]<>"",Table1[[#This Row],[PR Aktual (tanggal)]]<=Table1[[#This Row],[PLAN PR-PO ABJ finish]]),"Sudah, OnSchedule",IF(AND(Table1[[#This Row],[PR Aktual (tanggal)]]<>"",Table1[[#This Row],[PR Aktual (tanggal)]]>Table1[[#This Row],[PLAN PR-PO ABJ finish]]),"Sudah, Delay")))) -> Sudah, OnSchedule | DF5: 45250 | DG5: AJCPOV-2300148 | DH5: 537590677279 | DI5: =IF(AND(Table1[[#This Row],[PO Aktual (tanggal)]]="",Table1[[#This Row],[PLAN PR-PO ABJ finish]]>NOW()),"Belum, OnSchedule",IF(AND(Table1[[#This Row],[PO Aktual (tanggal)]]="",Table1[[#This Row],[PLAN PR-PO ABJ finish]]<NOW()),"Belum, Delay",IF(AND(Table1[[#This Row],[PO Aktual (tanggal)]]<>"",Table1[[#This Row],[PO Aktual (tanggal)]]<Table1[[#This Row],[PLAN PR-PO ABJ finish]]),"Sudah, OnSchedule",IF(AND(Table1[[#This Row],[PO Aktual (tanggal)]]<>"",Table1[[#This Row],[PO Aktual (tanggal)]]>Table1[[#This Row],[PLAN PR-PO ABJ finish]]),"Sudah, Delay")))) -> Sudah, Delay | DJ5: 45229 | DK5: 45445 | DL5: 45520 | DM5: PR-UN/BPM/JTLBarat/2412/0366 | DN5: =IF(AND(Table1[[#This Row],[PR Jasa Aktual (tanggal)]]="",Table1[[#This Row],[PLAN PR-PO BPM Jasa finish]]>NOW()),"Belum, OnSchedule",IF(AND(Table1[[#This Row],[PR Jasa Aktual (tanggal)]]="",Table1[[#This Row],[PLAN PR-PO BPM Jasa finish]]<NOW()),"Belum, Delay",IF(AND(Table1[[#This Row],[PR Jasa Aktual (tanggal)]]<>"",Table1[[#This Row],[PR Jasa Aktual (tanggal)]]<=Table1[[#This Row],[PLAN PR-PO BPM Jasa finish]]),"Sudah, OnSchedule",IF(AND(Table1[[#This Row],[PR Jasa Aktual (tanggal)]]<>"",Table1[[#This Row],[PR Jasa Aktual (tanggal)]]>Table1[[#This Row],[PLAN PR-PO BPM Jasa finish]]),"Sudah, Delay")))) -> Sudah, Delay | DO5: 45657 | DP5: BPMPO-2405299 | DQ5: PT. KMU Konstruksi Indonesia | DR5: =IF(AND(Table1[[#This Row],[PO Jasa Aktual (tanggal)]]="",Table1[[#This Row],[PLAN PR-PO BPM Jasa finish]]>NOW()),"Belum, OnSchedule",IF(AND(Table1[[#This Row],[PO Jasa Aktual (tanggal)]]="",Table1[[#This Row],[PLAN PR-PO BPM Jasa finish]]<NOW()),"Belum, Delay",IF(AND(Table1[[#This Row],[PO Jasa Aktual (tanggal)]]<>"",Table1[[#This Row],[PO Jasa Aktual (tanggal)]]<Table1[[#This Row],[PLAN PR-PO BPM Jasa finish]]),"Sudah, OnSchedule",IF(AND(Table1[[#This Row],[PO Jasa Aktual (tanggal)]]<>"",Table1[[#This Row],[PO Jasa Aktual (tanggal)]]>Table1[[#This Row],[PLAN PR-PO BPM Jasa finish]]),"Sudah, Delay")))) -> Sudah, Delay | DS5: 45229 | DT5: #N/A | DU5: 45277 | DV5: #N/A | EA5: =IF(AND(Table1[[#This Row],[PR Material Aktual (tanggal)]]="",Table1[[#This Row],[PLAN PR-PO BPM Material finish]]>NOW()),"Belum, OnSchedule",IF(AND(Table1[[#This Row],[PR Material Aktual (tanggal)]]="",Table1[[#This Row],[PLAN PR-PO BPM Material finish]]<NOW()),"Belum, Delay",IF(AND(Table1[[#This Row],[PR Material Aktual (tanggal)]]<>"",Table1[[#This Row],[PR Material Aktual (tanggal)]]<Table1[[#This Row],[PLAN PR-PO BPM Material finish]]),"Sudah, OnSchedule",IF(AND(Table1[[#This Row],[PR Material Aktual (tanggal)]]<>"",Table1[[#This Row],[PR Material Aktual (tanggal)]]>Table1[[#This Row],[PLAN PR-PO BPM Material finish]]),"Sudah, Delay")))) -> Belum, Delay | EF5: 1 | EG5: 1 | EH5: =IF(Table1[[#This Row],[PO Material Aktual (%)]]>=100%,"Selesai PO = 100%",IF(Table1[[#This Row],[PO Material Aktual (%)]]>=50%,"Proses PO > 100%",IF(Table1[[#This Row],[PO Material Aktual (%)]]>0%,"Proses PO > 50%",IF(Table1[[#This Row],[PO Material Aktual (%)]]=0,"Belum PO = 0%")))) -> Selesai PO = 100% | EI5: =IF(AND(Table1[[#This Row],[Tanggal Selesai PO Material]]="",Table1[[#This Row],[PLAN PR-PO BPM Material finish]]>=NOW()),"Belum, OnSchedule",IF(AND(Table1[[#This Row],[Tanggal Selesai PO Material]]="",Table1[[#This Row],[PLAN PR-PO BPM Material finish]]<NOW()),"Belum, Delay",IF(AND(Table1[[#This Row],[Tanggal Selesai PO Material]]<>"",Table1[[#This Row],[Tanggal Selesai PO Material]]<=Table1[[#This Row],[PLAN PR-PO BPM Material finish]]),"Sudah, OnSchedule",IF(AND(Table1[[#This Row],[Tanggal Selesai PO Material]]<>"",Table1[[#This Row],[Tanggal Selesai PO Material]]>Table1[[#This Row],[PLAN PR-PO BPM Material finish]]),"Sudah, Delay")))) -> Belum, Delay | EJ5: 45278 | EK5: #N/A | EL5: 45564 | EM5: #N/A | EQ5: 1 | ER5: 1 | ES5: =IF(Table1[[#This Row],[Progres MOS]]>=100%,"Selesai MOS = 100%",IF(Table1[[#This Row],[Progres MOS]]>=50%,"Proses MOS > 100%",IF(Table1[[#This Row],[Progres MOS]]>0%,"Proses MOS > 50%",IF(Table1[[#This Row],[Progres MOS]]=0,"Belum MOS = 0%")))) -> Selesai MOS = 100% | ET5: =IF(AND(Table1[[#This Row],[Tanggal Selesai MOS]]="",Table1[[#This Row],[PLAN MOS finish]]>=NOW()),"Belum, OnSchedule",IF(AND(Table1[[#This Row],[Tanggal Selesai MOS]]="",Table1[[#This Row],[PLAN MOS finish]]<NOW()),"Belum, Delay",IF(AND(Table1[[#This Row],[Tanggal Selesai MOS]]<>"",Table1[[#This Row],[Tanggal Selesai MOS]]<=Table1[[#This Row],[PLAN MOS finish]]),"Sudah, OnSchedule",IF(AND(Table1[[#This Row],[Tanggal Selesai MOS]]<>"",Table1[[#This Row],[Tanggal Selesai MOS]]>Table1[[#This Row],[PLAN MOS finish]]),"Sudah, Delay")))) -> Belum, Delay | EV5: 45229 | EW5: #N/A | EX5: 45473 | EY5: #N/A | EZ5: 10.Izin Terbit | FA5: 10.Izin Terbit | FB5: Sudah | FC5: 45014 | FD5: Sudah | FF5: 45097 | FG5: Sudah | FH5: Sudah | FI5: 45187 | FJ5: Sudah | FK5: 45434 | FL5: 10.Izin Terbit | FM5: 45014 | FN5: =IF(Table1[[#This Row],[Tanggal Pengajuan Dokumen]]="","",Table1[[#This Row],[PLAN PERMIT start]]-Table1[[#This Row],[Tanggal Pengajuan Dokumen]]) -> 215 | FO5: 45434 | FP5: Izin Terbit | FR5: Izin Terbit | FS5: =IF(COUNTIF(EZ5:FR5,"*terbit*")>=1,"Sudah Terbit","On Going") -> Sudah Terbit | FT5: =IF(ISNUMBER(SEARCH("On Going",Table1[[#This Row],[Status Perizinan]])),"On Going",IF(ISNUMBER(SEARCH("Sudah Terbit",Table1[[#This Row],[Status Perizinan]])),"Selesai",IF(NOW()<Table1[[#This Row],[PLAN PERMIT start]],"Belum",IF(AND(NOW()>=Table1[[#This Row],[PLAN PERMIT start]],NOW()<=Table1[[#This Row],[PLAN PERMIT finish]]),"On Going","Terlambat")))) -> Selesai | FU5: =IF(Table1[[#This Row],[Status Izin]]="Selesai",Table1[[#This Row],[PLAN PERMIT finish]]-Table1[[#This Row],[Tanggal Terbit/ Target Izin Terbit]],ROUNDUP(Table1[[#This Row],[PLAN PERMIT finish]]-NOW(),0)) -> 39 | FV5: =IF(Table1[[#This Row],[Tanggal Terbit/ Target Izin Terbit]]="","Delay",IF(Table1[[#This Row],[Tanggal Terbit/ Target Izin Terbit]]<Table1[[#This Row],[PLAN PERMIT start]],"Ahead",IF(AND(Table1[[#This Row],[PLAN PERMIT start]]<=Table1[[#This Row],[Tanggal Terbit/ Target Izin Terbit]],Table1[[#This Row],[PLAN PERMIT finish]]>=Table1[[#This Row],[Tanggal Terbit/ Target Izin Terbit]]),"On Schedule",IF(Table1[[#This Row],[Tanggal Terbit/ Target Izin Terbit]]>Table1[[#This Row],[PLAN PERMIT finish]],"Delay")))) -> On Schedule | GA5: =IF(AND(Table1[[#This Row],[Aktual DPPK]]="",Table1[[#This Row],[PLAN Penyerahan DPPK]]>NOW()),"Belum, OnSchedule",IF(AND(Table1[[#This Row],[Aktual DPPK]]="",Table1[[#This Row],[PLAN Penyerahan DPPK]]<NOW()),"Belum, Delay",IF(AND(Table1[[#This Row],[Aktual DPPK]]<>"",Table1[[#This Row],[Aktual DPPK]]<=Table1[[#This Row],[PLAN Penyerahan DPPK]]),"Sudah, OnSchedule",IF(AND(Table1[[#This Row],[Aktual DPPK]]<>"",Table1[[#This Row],[Aktual DPPK]]>Table1[[#This Row],[PLAN Penyerahan DPPK]]),"Sudah, Delay")))) -> Belum, Delay | GB5: 45447 | GC5: 45414 | GD5: =IF(AND(Table1[[#This Row],[Tanggal Aktual PCM]]="",Table1[[#This Row],[PLAN PCM]]>NOW()),"Belum, OnSchedule",IF(AND(Table1[[#This Row],[Tanggal Aktual PCM]]="",Table1[[#This Row],[PLAN PCM]]<NOW()),"Belum, Delay",IF(AND(Table1[[#This Row],[Tanggal Aktual PCM]]<>"",Table1[[#This Row],[Tanggal Aktual PCM]]<=Table1[[#This Row],[PLAN PCM]]),"Sudah, OnSchedule",IF(AND(Table1[[#This Row],[Tanggal Aktual PCM]]<>"",Table1[[#This Row],[Tanggal Aktual PCM]]>=Table1[[#This Row],[PLAN PCM]]),"Sudah, Delay")))) -> Sudah, OnSchedule | GE5: 45454 | GF5: 45414 | GG5: =IF(AND(Table1[[#This Row],[Tanggal Aktual Kick Off]]="",Table1[[#This Row],[PLAN Kick Off]]>NOW()),"Belum, OnSchedule",IF(AND(Table1[[#This Row],[Tanggal Aktual Kick Off]]="",Table1[[#This Row],[PLAN Kick Off]]<NOW()),"Belum, Delay",IF(AND(Table1[[#This Row],[Tanggal Aktual Kick Off]]<>"",Table1[[#This Row],[Tanggal Aktual Kick Off]]<=Table1[[#This Row],[PLAN Kick Off]]),"Sudah, OnSchedule",IF(AND(Table1[[#This Row],[Tanggal Aktual Kick Off]]<>"",Table1[[#This Row],[Tanggal Aktual Kick Off]]>=Table1[[#This Row],[PLAN Kick Off]]),"Sudah, Delay")))) -> Sudah, OnSchedule | GH5: 45460 | GI5: 45466 | GJ5: 45443 | GK5: =IF(AND(Table1[[#This Row],[Tanggal Aktual MC-0]]="",Table1[[#This Row],[PLAN MC-0 finish]]>NOW()),"Belum, OnSchedule",IF(AND(Table1[[#This Row],[Tanggal Aktual MC-0]]="",Table1[[#This Row],[PLAN MC-0 finish]]<NOW()),"Belum, Delay",IF(AND(Table1[[#This Row],[Tanggal Aktual MC-0]]<>"",Table1[[#This Row],[Tanggal Aktual MC-0]]<Table1[[#This Row],[PLAN MC-0 finish]]),"Sudah, OnSchedule",IF(AND(Table1[[#This Row],[Tanggal Aktual MC-0]]<>"",Table1[[#This Row],[Tanggal Aktual MC-0]]>Table1[[#This Row],[PLAN MC-0 finish]]),"Sudah, Delay")))) -> Sudah, OnSchedule | GL5: 45474 | GM5: #N/A | GN5: 45641 | GO5: #N/A | GQ5: =IF(AND(Table1[[#This Row],[Aktual Selesai Konstruksi* (tanggal)]]="",Table1[[#This Row],[PLAN KONSTRUKSI finish]]>NOW()),"Belum, OnSchedule",IF(AND(Table1[[#This Row],[Aktual Selesai Konstruksi* (tanggal)]]="",Table1[[#This Row],[PLAN KONSTRUKSI finish]]<NOW()),"Belum, Delay",IF(AND(Table1[[#This Row],[Aktual Selesai Konstruksi* (tanggal)]]<>"",Table1[[#This Row],[Aktual Selesai Konstruksi* (tanggal)]]<Table1[[#This Row],[PLAN KONSTRUKSI finish]]),"Sudah, OnSchedule",IF(AND(Table1[[#This Row],[Aktual Selesai Konstruksi* (tanggal)]]<>"",Table1[[#This Row],[Aktual Selesai Konstruksi* (tanggal)]]>Table1[[#This Row],[PLAN KONSTRUKSI finish]]),"Sudah, Delay")))) -> Belum, Delay | GR5: - | GS5: - | GT5: 45637 | GU5: =IF(Table1[[#This Row],[Hydro Tes Actual (tanggal)]]<>"","Sudah","Belum") -> Sudah | GV5: - | GW5: - | GY5: =IF(Table1[[#This Row],[Interkoneksi Actual (tanggal)]]<>"","Sudah","Belum") -> Belum | GZ5: - | HA5: - | HB5: 44965 | HC5: =IF(Table1[[#This Row],[Flushing Actual (tanggal)]]<>"","Sudah","Belum") -> Sudah | HD5: 45614 | HE5: #N/A | HF5: 45620 | HG5: 45699 | HH5: =IF(AND(Table1[[#This Row],[TC Aktual (tanggal)]]="",Table1[[#This Row],[PLAN TC finish]]>NOW()),"Belum, OnSchedule",IF(AND(Table1[[#This Row],[TC Aktual (tanggal)]]="",Table1[[#This Row],[PLAN TC finish]]<NOW()),"Belum, Delay",IF(AND(Table1[[#This Row],[TC Aktual (tanggal)]]<>"",Table1[[#This Row],[TC Aktual (tanggal)]]<Table1[[#This Row],[PLAN TC finish]]),"Sudah, OnSchedule",IF(AND(Table1[[#This Row],[TC Aktual (tanggal)]]<>"",Table1[[#This Row],[TC Aktual (tanggal)]]>Table1[[#This Row],[PLAN TC finish]]),"Sudah, Delay")))) -> Sudah, Delay | HI5: - | HJ5: - | HM5: 45646 | HN5: 45646 | HO5: #N/A | HQ5: 45737 | HR5: =IF(AND(Table1[[#This Row],[BA MC-100 Aktual (Verifikasi)]]="",Table1[[#This Row],[PLAN MC-100 finish]]>NOW()),"Belum, OnSchedule",IF(AND(Table1[[#This Row],[BA MC-100 Aktual (Verifikasi)]]="",Table1[[#This Row],[PLAN MC-100 finish]]<NOW()),"Belum, Delay",IF(AND(Table1[[#This Row],[BA MC-100 Aktual (Verifikasi)]]<>"",Table1[[#This Row],[BA MC-100 Aktual (Verifikasi)]]<Table1[[#This Row],[PLAN MC-100 finish]]),"Sudah, OnSchedule",IF(AND(Table1[[#This Row],[BA MC-100 Aktual (Verifikasi)]]<>"",Table1[[#This Row],[BA MC-100 Aktual (Verifikasi)]]>Table1[[#This Row],[PLAN MC-100 finish]]),"Sudah, Delay")))) -> Sudah, Delay | HS5: 45653 | HU5: 45653 | HW5: 45751 | HX5: =IF(AND(Table1[[#This Row],[Aktual Submit DPPP (tanggal)]]="",Table1[[#This Row],[PLAN DPPP finish]]>NOW()),"Belum, OnSchedule",IF(AND(Table1[[#This Row],[Aktual Submit DPPP (tanggal)]]="",Table1[[#This Row],[PLAN DPPP finish]]<NOW()),"Belum, Delay",IF(AND(Table1[[#This Row],[Aktual Submit DPPP (tanggal)]]<>"",Table1[[#This Row],[Aktual Submit DPPP (tanggal)]]<Table1[[#This Row],[PLAN DPPP finish]]),"Sudah, OnSchedule",IF(AND(Table1[[#This Row],[Aktual Submit DPPP (tanggal)]]<>"",Table1[[#This Row],[Aktual Submit DPPP (tanggal)]]>Table1[[#This Row],[PLAN DPPP finish]]),"Sudah, Delay")))) -> Sudah, Delay | IC5: =IFERROR(ROUND((Table1[[#This Row],[PLAN TC finish]]-Table1[[#This Row],[PLAN MC-0 start]])/30,2),"") -> 5.33 | ID5: =DATEDIF(Table1[[#This Row],[PLAN MC-0 start]],Table1[[#This Row],[PLAN TC finish]],"m") -> 5
B6: =SUBTOTAL(3,$D$5:D6) -> 2 | C6: 2 | D6: SPAM Jatiluhur Hilir | E6: NPP23JTAA06 | F6: A6 - Pondok Kopi DN1000 | G6: 45752 | H6: MS | I6: Trunk Main | K6: Muhrojin | L6: Pipa | M6: PMO 2 | N6: 1112 | O6: m | P6: =IF(NOW()>Table1[[#This Row],[PLAN MC-100 start]],"Selesai Fisik dan Dokumen",IF(AND(Table1[[#This Row],[PLAN MC-100 start]]<=NOW(),NOW()<=Table1[[#This Row],[PLAN MC-100 finish]]),"MC-100",IF(AND(Table1[[#This Row],[PLAN TC start]]<=NOW(),NOW()<=Table1[[#This Row],[PLAN TC finish]]),"Tes Com",IF(AND(Table1[[#This Row],[PLAN KONSTRUKSI start]]<=NOW(),NOW()<=Table1[[#This Row],[PLAN KONSTRUKSI finish]]),"Proses Konstruksi",IF(AND(Table1[[#This Row],[PLAN MOS start]]<=NOW(),NOW()<=Table1[[#This Row],[PLAN MOS finish]]),"Proses MOS",IF(AND(Table1[[#This Row],[PLAN MC-0 start]]<=NOW(),NOW()<=Table1[[#This Row],[PLAN MC-0 finish]]),"MC-0",IF(AND(Table1[[#This Row],[PLAN PR-PO BPM Jasa start]]<=NOW(),NOW()<=Table1[[#This Row],[PLAN PR-PO BPM Material finish]]),"PR-PO BPM",IF(AND(Table1[[#This Row],[PLAN PR-PO ABJ start]]<=NOW(),NOW()<=Table1[[#This Row],[PLAN PR-PO ABJ finish]]),"PR-PO ABJ",IF(NOW()<Table1[[#This Row],[PLAN PR-PO ABJ finish]],"Persiapan",""))))))))) -> Selesai Fisik dan Dokumen | Q6: =IF(LEFT(Table1[[#This Row],[Review DPPP]],5)="Sudah","DPPP",IF(LEFT(Table1[[#This Row],[Review MC-100]],5)="Sudah","MC-100",IF(LEFT(Table1[[#This Row],[Status TC]],5)="Sudah","Tes Com",IF(Table1[[#This Row],[Status Flushing]]="Sudah","Flushing",IF(Table1[[#This Row],[Total Panjang Pipa Aktual (Sum->)3]]>0,"Proses Konstruksi",IF(LEFT(Table1[[#This Row],[Review MC-0]],5)="Sudah","MC-0",IF(LEFT(Table1[[#This Row],[Review Kick Off]],5)="Sudah","Kick Off Meeting",IF(LEFT(Table1[[#This Row],[Review PCM]],5)="Sudah","PCM",IF(LEFT(Table1[[#This Row],[Status MOS]],10)="Proses MOS","Proses MOS",IF(LEFT(Table1[[#This Row],[Review PO Jasa BPM]],5)="Sudah","PO Jasa BPM",IF(LEFT(Table1[[#This Row],[Review PR Jasa BPM]],5)="Sudah","PR Jasa BPM",IF(LEFT(Table1[[#This Row],[Review PO Material BPM]],5)="Sudah","PO Material BPM",IF(LEFT(Table1[[#This Row],[Review PR Material BPM]],5)="Sudah","PR Material BPM",IF(LEFT(Table1[[#This Row],[Review PO ABJ]],5)="Sudah","PO ABJ",IF(LEFT(Table1[[#This Row],[Review PR ABJ]],5)="Sudah","PR ABJ","Persiapan"))))))))))))))) -> DPPP | R6: #N/A | S6: 1 | T6: =Table1[[#This Row],[Progres Total Aktual (%)]] -> 1 | U6: =Table1[[#This Row],[Progres Aktual (%)]]-Table1[[#This Row],[Target Progres (%)]] -> 0 | V6: =Table1[[#This Row],["Volume BA MC-0"]] -> 1083 | W6: =Table1[[#This Row],[Total Panjang Pipa Aktual (Sum->)3]] -> 1071.72 | Y6: Jl. Mawar Merah II, Kel. Pondok Kopi, Kec. Duren Sawit | Z6: 50476486470 | AA6: =ROUND((Table1[[#This Row],[Nilai RAB Jaringan (Exclude Ppn)]]-Table1[[#This Row],[RAB Perizinan]])*1.11+Table1[[#This Row],[RAB Perizinan]],0) -> 0 | AB6: =SUM(Table1[[#This Row],[RAB Kegiatan Umum]:[RAB Perizinan]]) -> 0 | AG6: 0 | AH6: =SUM(Table1[[#This Row],[Bobot Keg Umum]:[Bobot Perizinan]]) -> #DIV/0! | AI6: =Table1[[#This Row],[RAB Kegiatan Umum]]/Table1[[#This Row],[Nilai RAB Jaringan (Exclude Ppn)]] -> #DIV/0! | AJ6: =Table1[[#This Row],[RAB Pemasangan]]/Table1[[#This Row],[Nilai RAB Jaringan (Exclude Ppn)]] -> #DIV/0! | AK6: =Table1[[#This Row],[RAB Pengadaan]]/Table1[[#This Row],[Nilai RAB Jaringan (Exclude Ppn)]] -> #DIV/0! | AL6: =Table1[[#This Row],[RAB Perizinan]]/Table1[[#This Row],[Nilai RAB Jaringan (Exclude Ppn)]] -> #DIV/0! | AN6: 1083 | AO6: =SUM(Table1[[#This Row],[Pipa 63 mm]:[Pipa 1,800 mm]]) -> 0 | BJ6: =SUM(Table1[[#This Row],[Pipa 63 mm2]:[Pipa 1,800 mm21]]) -> 1071.72 | BY6: =380.8+644.7+46.22 -> 1071.72 | CE6: 0 | CI6: =SUM(CE6:CH6) -> 0 | CJ6: =IF((Table1[[#This Row],["Volume BA MC-0"]]-Table1[[#This Row],[Total Panjang Pipa Aktual (Sum->)3]]-Table1[[#This Row],[Total Volume tidak dapat dipasang]])>=0,Table1[[#This Row],["Volume BA MC-0"]]-Table1[[#This Row],[Total Panjang Pipa Aktual (Sum->)3]]-Table1[[#This Row],[Total Volume tidak dapat dipasang]],0) -> 11.28 | CP6: =IFERROR(IF(Table1[[#This Row],[Nilai RNA Update]]>0,Table1[[#This Row],[Nilai RNA Update]]/Table1[[#This Row],[Nilai RNA Update]],IF(Table1[[#This Row],[VOWD Total (Rp)]]=0,IF(LEFT(Table1[[#This Row],[Review PO Material BPM]],5)="Sudah",Table1[[#This Row],[Progres MOS]]*80%*Table1[[#This Row],[Bobot Pengadaan]],Table1[[#This Row],[Progres MOS]]*60%*Table1[[#This Row],[Bobot Pengadaan]]),Table1[[#This Row],[VOWD Total (Rp)]]/Table1[[#This Row],[Kontrol Nilai RAB Jaringan (Include Ppn)]])),0) -> 1 | CQ6: =IFERROR(Table1[[#This Row],[Progres Keg. Umum (%)]]*Table1[[#This Row],[Nilai RAB Jaringan (file pa aji)]],0) -> 0 | CR6: =IFERROR(Table1[[#This Row],[Progres MOS (%)]]*Table1[[#This Row],[Nilai RAB Jaringan (file pa aji)]],0) -> 0 | CS6: =IFERROR(Table1[[#This Row],[Progres Pemasangan (%)]]*Table1[[#This Row],[Nilai RAB Jaringan (file pa aji)]],0) -> 0 | CT6: =IFERROR(Table1[[#This Row],[Progres Perizinan (%)]]*Table1[[#This Row],[Nilai RAB Jaringan (file pa aji)]],0) -> 0 | CU6: 51407089365 | CV6: 51407089365 | CW6: 51407089365 | CX6: =_xlfn.XLOOKUP(Table1[[#This Row],[Kode Program]],'[1]Breakdown VOWD Greenfield'!$E:$E,'[1]Breakdown VOWD Greenfield'!$AT:$AT) -> 51407089365 | CZ6: 45194 | DA6: 45228 | DB6: 45240 | DC6: AJC/2023/11/Q800/362 | DD6: 50448936470 | DE6: =IF(AND(Table1[[#This Row],[PR Aktual (tanggal)]]="",Table1[[#This Row],[PLAN PR-PO ABJ finish]]>=NOW()),"Belum, OnSchedule",IF(AND(Table1[[#This Row],[PR Aktual (tanggal)]]="",Table1[[#This Row],[PLAN PR-PO ABJ finish]]<NOW()),"Belum, Delay",IF(AND(Table1[[#This Row],[PR Aktual (tanggal)]]<>"",Table1[[#This Row],[PR Aktual (tanggal)]]<=Table1[[#This Row],[PLAN PR-PO ABJ finish]]),"Sudah, OnSchedule",IF(AND(Table1[[#This Row],[PR Aktual (tanggal)]]<>"",Table1[[#This Row],[PR Aktual (tanggal)]]>Table1[[#This Row],[PLAN PR-PO ABJ finish]]),"Sudah, Delay")))) -> Sudah, Delay | DF6: 45250 | DG6: AJCPOV-2300148 | DH6: 50448936470 | DI6: =IF(AND(Table1[[#This Row],[PO Aktual (tanggal)]]="",Table1[[#This Row],[PLAN PR-PO ABJ finish]]>NOW()),"Belum, OnSchedule",IF(AND(Table1[[#This Row],[PO Aktual (tanggal)]]="",Table1[[#This Row],[PLAN PR-PO ABJ finish]]<NOW()),"Belum, Delay",IF(AND(Table1[[#This Row],[PO Aktual (tanggal)]]<>"",Table1[[#This Row],[PO Aktual (tanggal)]]<Table1[[#This Row],[PLAN PR-PO ABJ finish]]),"Sudah, OnSchedule",IF(AND(Table1[[#This Row],[PO Aktual (tanggal)]]<>"",Table1[[#This Row],[PO Aktual (tanggal)]]>Table1[[#This Row],[PLAN PR-PO ABJ finish]]),"Sudah, Delay")))) -> Sudah, Delay | DJ6: 45229 | DK6: 45445 | DL6: 45274.711 | DM6: PR/BPM/JTLTimur/2312/0007 | DN6: =IF(AND(Table1[[#This Row],[PR Jasa Aktual (tanggal)]]="",Table1[[#This Row],[PLAN PR-PO BPM Jasa finish]]>NOW()),"Belum, OnSchedule",IF(AND(Table1[[#This Row],[PR Jasa Aktual (tanggal)]]="",Table1[[#This Row],[PLAN PR-PO BPM Jasa finish]]<NOW()),"Belum, Delay",IF(AND(Table1[[#This Row],[PR Jasa Aktual (tanggal)]]<>"",Table1[[#This Row],[PR Jasa Aktual (tanggal)]]<=Table1[[#This Row],[PLAN PR-PO BPM Jasa finish]]),"Sudah, OnSchedule",IF(AND(Table1[[#This Row],[PR Jasa Aktual (tanggal)]]<>"",Table1[[#This Row],[PR Jasa Aktual (tanggal)]]>Table1[[#This Row],[PLAN PR-PO BPM Jasa finish]]),"Sudah, Delay")))) -> Sudah, OnSchedule | DO6: 45456.292 | DP6: BPMPO-2402410 | DQ6: PT. KMU Konstruksi Indonesia | DR6: =IF(AND(Table1[[#This Row],[PO Jasa Aktual (tanggal)]]="",Table1[[#This Row],[PLAN PR-PO BPM Jasa finish]]>NOW()),"Belum, OnSchedule",IF(AND(Table1[[#This Row],[PO Jasa Aktual (tanggal)]]="",Table1[[#This Row],[PLAN PR-PO BPM Jasa finish]]<NOW()),"Belum, Delay",IF(AND(Table1[[#This Row],[PO Jasa Aktual (tanggal)]]<>"",Table1[[#This Row],[PO Jasa Aktual (tanggal)]]<Table1[[#This Row],[PLAN PR-PO BPM Jasa finish]]),"Sudah, OnSchedule",IF(AND(Table1[[#This Row],[PO Jasa Aktual (tanggal)]]<>"",Table1[[#This Row],[PO Jasa Aktual (tanggal)]]>Table1[[#This Row],[PLAN PR-PO BPM Jasa finish]]),"Sudah, Delay")))) -> Sudah, Delay | DS6: 45229 | DT6: #N/A | DU6: 45277 | DV6: #N/A | EA6: =IF(AND(Table1[[#This Row],[PR Material Aktual (tanggal)]]="",Table1[[#This Row],[PLAN PR-PO BPM Material finish]]>NOW()),"Belum, OnSchedule",IF(AND(Table1[[#This Row],[PR Material Aktual (tanggal)]]="",Table1[[#This Row],[PLAN PR-PO BPM Material finish]]<NOW()),"Belum, Delay",IF(AND(Table1[[#This Row],[PR Material Aktual (tanggal)]]<>"",Table1[[#This Row],[PR Material Aktual (tanggal)]]<Table1[[#This Row],[PLAN PR-PO BPM Material finish]]),"Sudah, OnSchedule",IF(AND(Table1[[#This Row],[PR Material Aktual (tanggal)]]<>"",Table1[[#This Row],[PR Material Aktual (tanggal)]]>Table1[[#This Row],[PLAN PR-PO BPM Material finish]]),"Sudah, Delay")))) -> Belum, Delay | EF6: 1 | EG6: 1 | EH6: =IF(Table1[[#This Row],[PO Material Aktual (%)]]>=100%,"Selesai PO = 100%",IF(Table1[[#This Row],[PO Material Aktual (%)]]>=50%,"Proses PO > 100%",IF(Table1[[#This Row],[PO Material Aktual (%)]]>0%,"Proses PO > 50%",IF(Table1[[#This Row],[PO Material Aktual (%)]]=0,"Belum PO = 0%")))) -> Selesai PO = 100% | EI6: =IF(AND(Table1[[#This Row],[Tanggal Selesai PO Material]]="",Table1[[#This Row],[PLAN PR-PO BPM Material finish]]>=NOW()),"Belum, OnSchedule",IF(AND(Table1[[#This Row],[Tanggal Selesai PO Material]]="",Table1[[#This Row],[PLAN PR-PO BPM Material finish]]<NOW()),"Belum, Delay",IF(AND(Table1[[#This Row],[Tanggal Selesai PO Material]]<>"",Table1[[#This Row],[Tanggal Selesai PO Material]]<=Table1[[#This Row],[PLAN PR-PO BPM Material finish]]),"Sudah, OnSchedule",IF(AND(Table1[[#This Row],[Tanggal Selesai PO Material]]<>"",Table1[[#This Row],[Tanggal Selesai PO Material]]>Table1[[#This Row],[PLAN PR-PO BPM Material finish]]),"Sudah, Delay")))) -> Belum, Delay | EJ6: 45278 | EK6: #N/A | EL6: 45564 | EM6: #N/A | EQ6: 1 | ER6: 1 | ES6: =IF(Table1[[#This Row],[Progres MOS]]>=100%,"Selesai MOS = 100%",IF(Table1[[#This Row],[Progres MOS]]>=50%,"Proses MOS > 100%",IF(Table1[[#This Row],[Progres MOS]]>0%,"Proses MOS > 50%",IF(Table1[[#This Row],[Progres MOS]]=0,"Belum MOS = 0%")))) -> Selesai MOS = 100% | ET6: =IF(AND(Table1[[#This Row],[Tanggal Selesai MOS]]="",Table1[[#This Row],[PLAN MOS finish]]>=NOW()),"Belum, OnSchedule",IF(AND(Table1[[#This Row],[Tanggal Selesai MOS]]="",Table1[[#This Row],[PLAN MOS finish]]<NOW()),"Belum, Delay",IF(AND(Table1[[#This Row],[Tanggal Selesai MOS]]<>"",Table1[[#This Row],[Tanggal Selesai MOS]]<=Table1[[#This Row],[PLAN MOS finish]]),"Sudah, OnSchedule",IF(AND(Table1[[#This Row],[Tanggal Selesai MOS]]<>"",Table1[[#This Row],[Tanggal Selesai MOS]]>Table1[[#This Row],[PLAN MOS finish]]),"Sudah, Delay")))) -> Belum, Delay | EV6: 45229 | EW6: #N/A | EX6: 45473 | EY6: #N/A | EZ6: 10.Izin Terbit | FA6: 10.Izin Terbit | FB6: Sudah | FC6: 45013 | FD6: Sudah | FF6: 45097 | FG6: Sudah | FH6: Sudah | FI6: 45187 | FJ6: Sudah | FK6: 45434 | FL6: 10.Izin Terbit | FM6: 45013 | FN6: =IF(Table1[[#This Row],[Tanggal Pengajuan Dokumen]]="","",Table1[[#This Row],[PLAN PERMIT start]]-Table1[[#This Row],[Tanggal Pengajuan Dokumen]]) -> 216 | FO6: 45434 | FS6: =IF(COUNTIF(EZ6:FR6,"*terbit*")>=1,"Sudah Terbit","On Going") -> Sudah Terbit | FT6: =IF(ISNUMBER(SEARCH("On Going",Table1[[#This Row],[Status Perizinan]])),"On Going",IF(ISNUMBER(SEARCH("Sudah Terbit",Table1[[#This Row],[Status Perizinan]])),"Selesai",IF(NOW()<Table1[[#This Row],[PLAN PERMIT start]],"Belum",IF(AND(NOW()>=Table1[[#This Row],[PLAN PERMIT start]],NOW()<=Table1[[#This Row],[PLAN PERMIT finish]]),"On Going","Terlambat")))) -> Selesai | FU6: =IF(Table1[[#This Row],[Status Izin]]="Selesai",Table1[[#This Row],[PLAN PERMIT finish]]-Table1[[#This Row],[Tanggal Terbit/ Target Izin Terbit]],ROUNDUP(Table1[[#This Row],[PLAN PERMIT finish]]-NOW(),0)) -> 39 | FV6: =IF(Table1[[#This Row],[Tanggal Terbit/ Target Izin Terbit]]="","Delay",IF(Table1[[#This Row],[Tanggal Terbit/ Target Izin Terbit]]<Table1[[#This Row],[PLAN PERMIT start]],"Ahead",IF(AND(Table1[[#This Row],[PLAN PERMIT start]]<=Table1[[#This Row],[Tanggal Terbit/ Target Izin Terbit]],Table1[[#This Row],[PLAN PERMIT finish]]>=Table1[[#This Row],[Tanggal Terbit/ Target Izin Terbit]]),"On Schedule",IF(Table1[[#This Row],[Tanggal Terbit/ Target Izin Terbit]]>Table1[[#This Row],[PLAN PERMIT finish]],"Delay")))) -> On Schedule | GA6: =IF(AND(Table1[[#This Row],[Aktual DPPK]]="",Table1[[#This Row],[PLAN Penyerahan DPPK]]>NOW()),"Belum, OnSchedule",IF(AND(Table1[[#This Row],[Aktual DPPK]]="",Table1[[#This Row],[PLAN Penyerahan DPPK]]<NOW()),"Belum, Delay",IF(AND(Table1[[#This Row],[Aktual DPPK]]<>"",Table1[[#This Row],[Aktual DPPK]]<=Table1[[#This Row],[PLAN Penyerahan DPPK]]),"Sudah, OnSchedule",IF(AND(Table1[[#This Row],[Aktual DPPK]]<>"",Table1[[#This Row],[Aktual DPPK]]>Table1[[#This Row],[PLAN Penyerahan DPPK]]),"Sudah, Delay")))) -> Belum, Delay | GB6: 45447 | GC6: 45414 | GD6: =IF(AND(Table1[[#This Row],[Tanggal Aktual PCM]]="",Table1[[#This Row],[PLAN PCM]]>NOW()),"Belum, OnSchedule",IF(AND(Table1[[#This Row],[Tanggal Aktual PCM]]="",Table1[[#This Row],[PLAN PCM]]<NOW()),"Belum, Delay",IF(AND(Table1[[#This Row],[Tanggal Aktual PCM]]<>"",Table1[[#This Row],[Tanggal Aktual PCM]]<=Table1[[#This Row],[PLAN PCM]]),"Sudah, OnSchedule",IF(AND(Table1[[#This Row],[Tanggal Aktual PCM]]<>"",Table1[[#This Row],[Tanggal Aktual PCM]]>=Table1[[#This Row],[PLAN PCM]]),"Sudah, Delay")))) -> Sudah, OnSchedule | GE6: 45454 | GF6: 45414 | GG6: =IF(AND(Table1[[#This Row],[Tanggal Aktual Kick Off]]="",Table1[[#This Row],[PLAN Kick Off]]>NOW()),"Belum, OnSchedule",IF(AND(Table1[[#This Row],[Tanggal Aktual Kick Off]]="",Table1[[#This Row],[PLAN Kick Off]]<NOW()),"Belum, Delay",IF(AND(Table1[[#This Row],[Tanggal Aktual Kick Off]]<>"",Table1[[#This Row],[Tanggal Aktual Kick Off]]<=Table1[[#This Row],[PLAN Kick Off]]),"Sudah, OnSchedule",IF(AND(Table1[[#This Row],[Tanggal Aktual Kick Off]]<>"",Table1[[#This Row],[Tanggal Aktual Kick Off]]>=Table1[[#This Row],[PLAN Kick Off]]),"Sudah, Delay")))) -> Sudah, OnSchedule | GH6: 45460 | GI6: 45466 | GJ6: 45443 | GK6: =IF(AND(Table1[[#This Row],[Tanggal Aktual MC-0]]="",Table1[[#This Row],[PLAN MC-0 finish]]>NOW()),"Belum, OnSchedule",IF(AND(Table1[[#This Row],[Tanggal Aktual MC-0]]="",Table1[[#This Row],[PLAN MC-0 finish]]<NOW()),"Belum, Delay",IF(AND(Table1[[#This Row],[Tanggal Aktual MC-0]]<>"",Table1[[#This Row],[Tanggal Aktual MC-0]]<Table1[[#This Row],[PLAN MC-0 finish]]),"Sudah, OnSchedule",IF(AND(Table1[[#This Row],[Tanggal Aktual MC-0]]<>"",Table1[[#This Row],[Tanggal Aktual MC-0]]>Table1[[#This Row],[PLAN MC-0 finish]]),"Sudah, Delay")))) -> Sudah, OnSchedule | GL6: 45474 | GM6: #N/A | GN6: 45641 | GO6: #N/A | GQ6: =IF(AND(Table1[[#This Row],[Aktual Selesai Konstruksi* (tanggal)]]="",Table1[[#This Row],[PLAN KONSTRUKSI finish]]>NOW()),"Belum, OnSchedule",IF(AND(Table1[[#This Row],[Aktual Selesai Konstruksi* (tanggal)]]="",Table1[[#This Row],[PLAN KONSTRUKSI finish]]<NOW()),"Belum, Delay",IF(AND(Table1[[#This Row],[Aktual Selesai Konstruksi* (tanggal)]]<>"",Table1[[#This Row],[Aktual Selesai Konstruksi* (tanggal)]]<Table1[[#This Row],[PLAN KONSTRUKSI finish]]),"Sudah, OnSchedule",IF(AND(Table1[[#This Row],[Aktual Selesai Konstruksi* (tanggal)]]<>"",Table1[[#This Row],[Aktual Selesai Konstruksi* (tanggal)]]>Table1[[#This Row],[PLAN KONSTRUKSI finish]]),"Sudah, Delay")))) -> Belum, Delay | GR6: - | GS6: - | GT6: 45635 | GU6: =IF(Table1[[#This Row],[Hydro Tes Actual (tanggal)]]<>"","Sudah","Belum") -> Sudah | GV6: - | GW6: - | GX6: 45563 | GY6: =IF(Table1[[#This Row],[Interkoneksi Actual (tanggal)]]<>"","Sudah","Belum") -> Sudah | GZ6: - | HA6: - | HB6: 44965 | HC6: =IF(Table1[[#This Row],[Flushing Actual (tanggal)]]<>"","Sudah","Belum") -> Sudah | HD6: 45614 | HE6: #N/A | HF6: 45620 | HG6: 45699 | HH6: =IF(AND(Table1[[#This Row],[TC Aktual (tanggal)]]="",Table1[[#This Row],[PLAN TC finish]]>NOW()),"Belum, OnSchedule",IF(AND(Table1[[#This Row],[TC Aktual (tanggal)]]="",Table1[[#This Row],[PLAN TC finish]]<NOW()),"Belum, Delay",IF(AND(Table1[[#This Row],[TC Aktual (tanggal)]]<>"",Table1[[#This Row],[TC Aktual (tanggal)]]<Table1[[#This Row],[PLAN TC finish]]),"Sudah, OnSchedule",IF(AND(Table1[[#This Row],[TC Aktual (tanggal)]]<>"",Table1[[#This Row],[TC Aktual (tanggal)]]>Table1[[#This Row],[PLAN TC finish]]),"Sudah, Delay")))) -> Sudah, Delay | HI6: - | HJ6: - | HM6: 45646 | HN6: 45646 | HO6: #N/A | HQ6: 45737 | HR6: =IF(AND(Table1[[#This Row],[BA MC-100 Aktual (Verifikasi)]]="",Table1[[#This Row],[PLAN MC-100 finish]]>NOW()),"Belum, OnSchedule",IF(AND(Table1[[#This Row],[BA MC-100 Aktual (Verifikasi)]]="",Table1[[#This Row],[PLAN MC-100 finish]]<NOW()),"Belum, Delay",IF(AND(Table1[[#This Row],[BA MC-100 Aktual (Verifikasi)]]<>"",Table1[[#This Row],[BA MC-100 Aktual (Verifikasi)]]<Table1[[#This Row],[PLAN MC-100 finish]]),"Sudah, OnSchedule",IF(AND(Table1[[#This Row],[BA MC-100 Aktual (Verifikasi)]]<>"",Table1[[#This Row],[BA MC-100 Aktual (Verifikasi)]]>Table1[[#This Row],[PLAN MC-100 finish]]),"Sudah, Delay")))) -> Sudah, Delay | HS6: 45653 | HU6: 45653 | HW6: 45751 | HX6: =IF(AND(Table1[[#This Row],[Aktual Submit DPPP (tanggal)]]="",Table1[[#This Row],[PLAN DPPP finish]]>NOW()),"Belum, OnSchedule",IF(AND(Table1[[#This Row],[Aktual Submit DPPP (tanggal)]]="",Table1[[#This Row],[PLAN DPPP finish]]<NOW()),"Belum, Delay",IF(AND(Table1[[#This Row],[Aktual Submit DPPP (tanggal)]]<>"",Table1[[#This Row],[Aktual Submit DPPP (tanggal)]]<Table1[[#This Row],[PLAN DPPP finish]]),"Sudah, OnSchedule",IF(AND(Table1[[#This Row],[Aktual Submit DPPP (tanggal)]]<>"",Table1[[#This Row],[Aktual Submit DPPP (tanggal)]]>Table1[[#This Row],[PLAN DPPP finish]]),"Sudah, Delay")))) -> Sudah, Delay | IC6: =IFERROR(ROUND((Table1[[#This Row],[PLAN TC finish]]-Table1[[#This Row],[PLAN MC-0 start]])/30,2),"") -> 5.33 | ID6: =DATEDIF(Table1[[#This Row],[PLAN MC-0 start]],Table1[[#This Row],[PLAN TC finish]],"m") -> 5
